Traceback (most recent call last):
  File "/home/codespace/.python/current/lib/python3.12/site-packages/jupyter_cache/executors/utils.py", line 58, in single_nb_execution
    executenb(
  File "/home/codespace/.local/lib/python3.12/site-packages/nbclient/client.py", line 1314, in execute
    return NotebookClient(nb=nb, resources=resources, km=km, **kwargs).execute()
           ^^^^^^^^^^^^^^^^^^^^^^^^^^^^^^^^^^^^^^^^^^^^^^^^^^^^^^^^^^^^^^^^^^^^^
  File "/home/codespace/.local/lib/python3.12/site-packages/jupyter_core/utils/__init__.py", line 165, in wrapped
    return loop.run_until_complete(inner)
           ^^^^^^^^^^^^^^^^^^^^^^^^^^^^^^
  File "/home/codespace/.python/current/lib/python3.12/asyncio/base_events.py", line 684, in run_until_complete
    return future.result()
           ^^^^^^^^^^^^^^^
  File "/home/codespace/.local/lib/python3.12/site-packages/nbclient/client.py", line 709, in async_execute
    await self.async_execute_cell(
  File "/home/codespace/.local/lib/python3.12/site-packages/nbclient/client.py", line 1062, in async_execute_cell
    await self._check_raise_for_error(cell, cell_index, exec_reply)
  File "/home/codespace/.local/lib/python3.12/site-packages/nbclient/client.py", line 918, in _check_raise_for_error
    raise CellExecutionError.from_cell_and_msg(cell, exec_reply_content)
nbclient.exceptions.CellExecutionError: An error occurred while executing the following cell:
------------------
# Ubah nilai Diagnosis dari M/B menjadi 1/0
df['Diagnosis'] = df['Diagnosis'].map({'M': 1, 'B': 0})

# Cek hasil transformasi
print(df['Diagnosis'].value_counts())

df_clean.to_csv("encode.csv", index=False)
------------------

----- stdout -----
Diagnosis
0    357
1    212
Name: count, dtype: int64
------------------

[0;31m---------------------------------------------------------------------------[0m
[0;31mNameError[0m                                 Traceback (most recent call last)
Cell [0;32mIn[12], line 7[0m
[1;32m      4[0m [38;5;66;03m# Cek hasil transformasi[39;00m
[1;32m      5[0m [38;5;28mprint[39m(df[[38;5;124m'[39m[38;5;124mDiagnosis[39m[38;5;124m'[39m][38;5;241m.[39mvalue_counts())
[0;32m----> 7[0m [43mdf_clean[49m[38;5;241m.[39mto_csv([38;5;124m"[39m[38;5;124mencode.csv[39m[38;5;124m"[39m, index[38;5;241m=[39m[38;5;28;01mFalse[39;00m)

[0;31mNameError[0m: name 'df_clean' is not defined

